<!DOCTYPE html>
<html lang="en">
<head>
  <meta charset="UTF-8">
  <meta name="viewport" content="width=device-width, initial-scale=1.0">
  <meta http-equiv="X-UA-Compatible" content="ie=edge">
  <title>08_promise的几个关键问题3</title>
</head>
<body>
  <script>
    /* 
    4.	promise.then()返回的是新的Promise实例，它的结果和状态由什么决定?
					(1)简单表达: 由then()所指定的回调函数执行的结果决定
					(2)详细表达:
							①如果抛出异常, 新promise变为rejected, reason为抛出的异常
							②如果返回的是非promise的任意值, 新promise变为resolved, value为返回的值
							③如果返回的是另一个新promise, 此promise的结果就会成为新promise的结果 
				
				promise.catch()返回的也是新的Promise实例，它的结果和状态由什么决定?
					(1)简单表达: 由catch()所指定的失败的回调函数执行的结果决定
					(2)详细表达:
							①如果抛出异常, 新promise变为rejected, reason为抛出的异常
							②如果返回的是非promise的任意值, 新promise变为resolved, value为返回的值
							③如果返回的是另一个新promise, 此promise的结果就会成为新promise的结果 
    */

		//	Promise.prototype.then()方法
		/* let p1 = new Promise((resolve,reject)=>{
			setTimeout(()=>{
				resolve('成功的数据')
			},1000)
		})

		p1.then(
			value => {
				console.log('成功的回调1',value)
				return new Promise((resolve,reject)=>{
					setTimeout(()=>{
						reject(1)
					},9000)
				})
			},
			reason => console.log('失败的回调1',reason),
		).then(
			value => console.log('成功的回调2',value),
			reason => console.log('失败的回调2',reason),
		) */

		/* ************************************************************************ */

		//Promise.prototype.catch()方法
		/* let p1 = new Promise((resolve,reject)=>{
			setTimeout(()=>{
				reject('失败的数据')
			},1000)
		})
		let a = p1.catch(
			reason => {
				console.log('失败的回调1',reason)
				return Promise.reject(900)
			}
		)
		a.then(
			value => console.log('成功的回调2',value),
			reason => console.log('失败的回调2',reason),
		) */

		//then与catch的组合使用
		let p1 = new Promise((resolve,reject)=>{
			setTimeout(()=>{
				resolve('atguigu')
			},1000)
		})

		//第一种方式
		/* p1.then(
			value => console.log('成功的回调1',value),
			reason => console.log('失败的回调1',reason),
		) */

		//第二种方式
		p1.then(
			value => console.log('成功的回调1',value),
			//reason => {throw reason} //如果then不指定失败的回调，相当与写了该行代码
		).catch(
			reason => console.log('失败的回调1',reason),
		)




  </script>
</body>
</html>